# Study how exception handling is implemented in C++ using try, catch, and throw blocks.

Exception handling in C++ allows you to gracefully handle runtime errors and exceptional conditions that may occur during program execution. It provides a mechanism to separate error-handling code from normal program logic, improving code readability and maintainability. Here's how exception handling is implemented in C++ using `try`, `catch`, and `throw` blocks:

### 1. `try`, `catch`, and `throw` Blocks:

- **`try` Block**: The `try` block is used to enclose the code that may potentially throw an exception.
- **`catch` Block**: The `catch` block is used to handle exceptions thrown within the corresponding `try` block.
- **`throw` Statement**: The `throw` statement is used to explicitly throw an exception when an error or exceptional condition occurs.

### Syntax:

```cpp
try {
    // Code that may throw an exception
    throw ExceptionType(); // Throw an exception explicitly
} catch (ExceptionType1& e1) {
    // Handle exception of type ExceptionType1
} catch (ExceptionType2& e2) {
    // Handle exception of type ExceptionType2
} catch (...) {
    // Handle any other type of exception (catch-all)
}
```

### Example:

```cpp
#include <iostream>

void divide(int num, int denom) {
    if (denom == 0) {
        throw std::invalid_argument("Division by zero exception");
    }
    std::cout << "Result of division: " << num / denom << std::endl;
}

int main() {
    try {
        divide(10, 0); // Potential division by zero
    } catch (const std::invalid_argument& e) {
        std::cerr << "Exception caught: " << e.what() << std::endl;
    }
    return 0;
}
```

In this example:

- The `divide` function attempts to perform integer division but throws an `std::invalid_argument` exception if the denominator is zero.
- The `main` function contains a `try` block that calls the `divide` function.
- If an exception is thrown within the `try` block, the corresponding `catch` block(s) are executed to handle the exception.
- In this case, the `catch` block catches the `std::invalid_argument` exception and prints an error message.

### Best Practices:

1. Use exception handling for exceptional conditions, not for regular control flow.
2. Catch exceptions by reference (`const` if not modifying) to avoid unnecessary object copying.
3. Provide informative error messages when throwing exceptions to aid in debugging.
4. Use multiple `catch` blocks to handle different types of exceptions separately.
5. Use a catch-all (`catch (...)`) block to handle unexpected exceptions or to perform cleanup tasks.

Exception handling in C++ provides a robust mechanism for dealing with errors and exceptional conditions, improving the reliability and maintainability of your code. By understanding and effectively using `try`, `catch`, and `throw` blocks, you can write more resilient and error-tolerant C++ programs.

---

# Understand the concept of exception propagation and how to handle different types of exceptions.

Exception propagation refers to the process by which an exception is passed from one part of the program to another until it is caught and handled. In C++, exceptions can propagate through function calls, allowing errors to be detected and handled at appropriate levels of abstraction. Here's how exception propagation works and how to handle different types of exceptions:

### 1. Exception Propagation Mechanism:

- When an exception is thrown within a function, the control flow is transferred to the nearest enclosing `try` block.
- If the exception is not caught within the current function, it propagates up the call stack to the caller function.
- This process continues until an appropriate `catch` block is found to handle the exception or until it reaches the top-level function (`main`), where the program terminates if the exception is not caught.

### 2. Handling Different Types of Exceptions:

- C++ allows you to handle different types of exceptions using multiple `catch` blocks, each targeting a specific exception type.
- Exception handling in C++ follows a hierarchical order, where more specific exception types are caught before more general ones.

### Example:

```cpp
#include <iostream>

void riskyOperation(int value) {
    if (value < 0) {
        throw std::invalid_argument("Invalid value: must be non-negative");
    } else if (value == 0) {
        throw std::runtime_error("Division by zero error");
    }
    std::cout << "Result: " << 10 / value << std::endl;
}

int main() {
    try {
        riskyOperation(5); // No exception thrown
        riskyOperation(0); // Throws runtime_error
        riskyOperation(-3); // Throws invalid_argument
    } catch (const std::invalid_argument& e) {
        std::cerr << "Invalid argument exception: " << e.what() << std::endl;
    } catch (const std::runtime_error& e) {
        std::cerr << "Runtime error exception: " << e.what() << std::endl;
    } catch (...) {
        std::cerr << "Unknown exception caught" << std::endl;
    }
    return 0;
}
```

In this example:

- The `riskyOperation` function performs a risky operation (division) and throws exceptions for invalid arguments or division by zero.
- In the `main` function, a `try` block is used to call `riskyOperation` with different arguments.
- The `catch` blocks handle different types of exceptions thrown by `riskyOperation`, with more specific exceptions caught first.

### Best Practices:

1. Catch exceptions at an appropriate level of abstraction, close to where they occur, to provide meaningful error handling and recovery.
2. Use multiple `catch` blocks to handle different types of exceptions separately, ensuring that each exception is handled appropriately.
3. Catch specific exceptions before more general ones to avoid ambiguity and ensure proper exception handling.
4. Provide informative error messages when throwing exceptions to aid in debugging and error diagnosis.
5. Use a catch-all (`catch (...)`) block to handle unexpected exceptions or to perform cleanup tasks.

By understanding exception propagation and how to handle different types of exceptions, you can write more robust and reliable C++ code that gracefully handles errors and exceptional conditions.
